Workbook
Name IDX: 'Comparison (Coverages)'!#REF!
Name IDX: 'gee vs genmod'!$A$46

Sheet Comparison (Coverages)
A1: SAMPLEMISS_1 - SAMPLEMISS_100 [NOMISS_V3]
A2: [PROC GEE][IND CORR][NO MI][NRadjClass][NOMISS V3][bghhsub_s2_v3_nr]
A3: Effect | B3: True Value | C3: Estimate | D3: Empirical Bias | E3: Relative Bias | F3: Empirical SE | G3: Estimated SE | H3: Relative SE difference | I3: Coverage | J3: P(reject H0)
A4: Intercept | B4: 107.0774 | C4: 107.0471 | D4: -0.03033 | E4: -0.000283 | F4: 2.9796 | G4: 2.9681 | H4: -0.003858 | I4: 0.97 | J4: 1
A5: age_strat_new | B5: -4.7686 | C5: -4.9159 | D5: -0.14724 | E5: 0.030877 | F5: 1.1843 | G5: 1.2117 | H5: 0.023085 | I5: 0.94 | J5: 0.95
A6: x12 | B6: 8.6967 | C6: 8.6256 | D6: -0.07107 | E6: -0.008172 | F6: 0.7408 | G6: 0.6923 | H6: -0.065511 | I6: 0.93 | J6: 1
A7: x17 | B7: -1.6103 | C7: -1.5361 | D7: 0.0742 | E7: -0.046077 | F7: 0.6952 | G7: 0.7363 | H7: 0.058994 | I7: 0.96 | J7: 0.57
A8: x18 | B8: -7.9152 | C8: -8.008 | D8: -0.09281 | E8: 0.011725 | F8: 0.9426 | G8: 0.9013 | H8: -0.043766 | I8: 0.97 | J8: 1
A9: x6 | B9: 5.8681 | C9: 5.87 | D9: 0.00186 | E9: 0.000317 | F9: 0.0492 | G9: 0.0539 | H9: 0.094943 | I9: 0.95 | J9: 1
A10: y_bmi | B10: 0.0284 | C10: 0.0271 | D10: -0.00133 | E10: -0.046859 | F10: 0.0369 | G10: 0.0347 | H10: -0.059184 | I10: 0.95 | J10: 0.15
A12: [PROC GENMOD][IND CORR][NO MI][NRadjClass][NOMISS V3][bghhsub_s2_v3_nr]
A13: Effect | B13: True Value | C13: Estimate | D13: Empirical Bias | E13: Relative Bias | F13: Empirical SE | G13: Estimated SE | H13: Relative SE difference | I13: Coverage | J13: P(reject H0)
A14: Intercept | B14: 107.0774 | C14: 107.0471 | D14: -0.03033 | E14: -0.000283 | F14: 2.9796 | G14: 2.9681 | H14: -0.003858 | I14: 0.97 | J14: 1
A15: age_strat_new | B15: -4.7686 | C15: -4.9159 | D15: -0.14724 | E15: 0.030877 | F15: 1.1843 | G15: 1.2117 | H15: 0.023085 | I15: 0.94 | J15: 0.95
A16: x12 | B16: 8.6967 | C16: 8.6256 | D16: -0.07107 | E16: -0.008172 | F16: 0.7408 | G16: 0.6923 | H16: -0.065511 | I16: 0.93 | J16: 1
A17: x17 | B17: -1.6103 | C17: -1.5361 | D17: 0.0742 | E17: -0.046077 | F17: 0.6952 | G17: 0.7363 | H17: 0.058994 | I17: 0.96 | J17: 0.57
A18: x18 | B18: -7.9152 | C18: -8.008 | D18: -0.09281 | E18: 0.011725 | F18: 0.9426 | G18: 0.9013 | H18: -0.043766 | I18: 0.97 | J18: 1
A19: x6 | B19: 5.8681 | C19: 5.87 | D19: 0.00186 | E19: 0.000317 | F19: 0.0492 | G19: 0.0539 | H19: 0.094943 | I19: 0.95 | J19: 1
A20: y_bmi | B20: 0.0284 | C20: 0.0271 | D20: -0.00133 | E20: -0.046859 | F20: 0.0369 | G20: 0.0347 | H20: -0.059184 | I20: 0.95 | J20: 0.15

Sheet Coverages
B1: GEE-Based True Values (SAMPLEMISS_1 - SAMPLEMISS_1000) | X1: SUDAAN-Based True Values (SAMPLEMISS_1 - SAMPLEMISS_1000)
B2: [IND CORR] | M2: [EXCH CORR] | X2: [IND CORR] | AI2: [EXCH CORR]
A3: [MI] | B3: [PROC GENMOD][IND CORR][MI][Logistic RR][bghhsub_s2] | M3: [PROC GENMOD][EXCH CORR][MI][Logistic RR][bghhsub_s2] | X3: [PROC GENMOD][IND CORR][MI][Logistic RR][bghhsub_s2][SUDAAN TRUE] | AI3: [PROC GENMOD][EXCH CORR][MI][Logistic RR][bghhsub_s2][SUDAAN TRUE] | AS3: [MI] | AU3: 1
B4: Effect | C4: True Value | D4: Estimate | E4: Empirical Bias | F4: Relative Bias | G4: Empirical SE | H4: Estimated SE | I4: Relative SE difference | J4: Coverage | K4: P(reject H0) | M4: Effect | N4: True Value | O4: Estimate | P4: Empirical Bias | Q4: Relative Bias | R4: Empirical SE | S4: Estimated SE | T4: Relative SE difference | U4: Coverage | V4: P(reject H0) | X4: Effect | Y4: True Value | Z4: Estimate | AA4: Empirical Bias | AB4: Relative Bias | AC4: Empirical SE | AD4: Estimated SE | AE4: Relative SE difference | AF4: Coverage | AG4: P(reject H0) | AI4: Effect | AJ4: True Value | AK4: Estimate | AL4: Empirical Bias | AM4: Relative Bias | AN4: Empirical SE | AO4: Estimated SE | AP4: Relative SE difference | AQ4: Coverage | AR4: P(reject H0) | AU4: IPW weights in MI step
B5: Intercept | C5: 107.0774 | D5: 106.93137 | E5: -0.14604 | F5: -0.00136 | G5: 1.972643 | H5: 2.049606 | I5: 0.039015 | J5: 0.96 | K5: 0 | M5: Intercept | N5: 105.9799 | O5: 107.12438 | P5: 1.14444 | Q5: 0.0108 | R5: 2.070067 | S5: 2.139845 | T5: 0.03371 | U5: 0.929 | V5: 0 | X5: Intercept | Y5: 107.08 | Z5: 106.93137 | AA5: -0.14604 | AB5: -0.00136 | AC5: 1.972643 | AD5: 2.049606 | AE5: 0.039015 | AF5: 0.96 | AG5: 0 | AI5: Intercept | AJ5: 106.81 | AK5: 107.12438 | AL5: 0.31193 | AM5: 0.00292 | AN5: 2.070067 | AO5: 2.139845 | AP5: 0.03371 | AQ5: 0.956 | AR5: 0 | AU5: V1 weights in fitting step
B6: age_strat_new | C6: -4.7686 | D6: -4.902213 | E6: -0.13357 | F6: 0.02801 | G6: 0.750303 | H6: 0.787318 | I6: 0.049333 | J6: 0.955 | K6: 0 | M6: age_strat_new | N6: -5.1666 | O6: -4.846042 | P6: 0.32053 | Q6: -0.06204 | R6: 0.819816 | S6: 0.858604 | T6: 0.04731 | U6: 0.951 | V6: 0 | X6: age_strat_new | Y6: -4.77 | Z6: -4.902213 | AA6: -0.13357 | AB6: 0.02801 | AC6: 0.750303 | AD6: 0.787318 | AE6: 0.049333 | AF6: 0.955 | AG6: 0 | AI6: age_strat_new | AJ6: -4.8 | AK6: -4.846042 | AL6: -0.04676 | AM6: 0.009743 | AN6: 0.819816 | AO6: 0.858604 | AP6: 0.04731 | AQ6: 0.96 | AR6: 0
B7: x12 | C7: 8.6967 | D7: 8.648262 | E7: -0.04844 | F7: -0.00557 | G7: 0.438764 | H7: 0.449743 | I7: 0.025023 | J7: 0.951 | K7: 0 | M7: x12 | N7: 8.6968 | O7: 8.665136 | P7: -0.0317 | Q7: -0.00365 | R7: 0.502496 | S7: 0.503363 | T7: 0.00172 | U7: 0.953 | V7: 0 | X7: x12 | Y7: 8.7 | Z7: 8.648262 | AA7: -0.04844 | AB7: -0.00557 | AC7: 0.438764 | AD7: 0.449743 | AE7: 0.025023 | AF7: 0.951 | AG7: 0 | AI7: x12 | AJ7: 8.7 | AK7: 8.665136 | AL7: -0.03707 | AM7: -0.00426 | AN7: 0.502496 | AO7: 0.503363 | AP7: 0.00172 | AQ7: 0.953 | AR7: 0 | AU7: IPW weights = base weights / RR
B8: x17 | C8: -1.6103 | D8: -1.505191 | E8: 0.1051 | F8: -0.06527 | G8: 0.462231 | H8: 0.48417 | I8: 0.047462 | J8: 0.961 | K8: 0 | M8: x17 | N8: -1.5934 | O8: -1.62199 | P8: -0.02856 | Q8: 0.01792 | R8: 0.496327 | S8: 0.514035 | T8: 0.03568 | U8: 0.954 | V8: 0 | X8: x17 | Y8: -1.61 | Z8: -1.505191 | AA8: 0.1051 | AB8: -0.06527 | AC8: 0.462231 | AD8: 0.48417 | AE8: 0.047462 | AF8: 0.961 | AG8: 0 | AI8: x17 | AJ8: -1.58 | AK8: -1.62199 | AL8: -0.04136 | AM8: 0.026169 | AN8: 0.496327 | AO8: 0.514035 | AP8: 0.03568 | AQ8: 0.959 | AR8: 0 | AU8: RR = visit-specific missing prob calculated from Logistic
B9: x18 | C9: -7.9152 | D9: -7.897294 | E9: 0.01788 | F9: -0.00226 | G9: 0.561621 | H9: 0.558598 | I9: -0.005382 | J9: 0.953 | K9: 0 | M9: x18 | N9: -7.9049 | O9: -7.802692 | P9: 0.1022 | Q9: -0.01293 | R9: 0.621461 | S9: 0.62462 | T9: 0.00508 | U9: 0.959 | V9: 0 | X9: x18 | Y9: -7.92 | Z9: -7.897294 | AA9: 0.01788 | AB9: -0.00226 | AC9: 0.561621 | AD9: 0.558598 | AE9: -0.005382 | AF9: 0.953 | AG9: 0 | AI9: x18 | AJ9: -7.78 | AK9: -7.802692 | AL9: -0.02626 | AM9: 0.003377 | AN9: 0.621461 | AO9: 0.62462 | AP9: 0.00508 | AQ9: 0.957 | AR9: 0
B10: x6 | C10: 5.8681 | D10: 5.864786 | E10: -0.00335 | F10: -0.00057 | G10: 0.037695 | H10: 0.039779 | I10: 0.055286 | J10: 0.968 | K10: 0 | M10: x6 | N10: 5.8287 | O10: 5.854467 | P10: 0.02581 | Q10: 0.00443 | R10: 0.036957 | S10: 0.039931 | T10: 0.08048 | U10: 0.942 | V10: 0 | X10: x6 | Y10: 5.87 | Z10: 5.864786 | AA10: -0.00335 | AB10: -0.00057 | AC10: 0.037695 | AD10: 0.039779 | AE10: 0.055286 | AF10: 0.968 | AG10: 0 | AI10: x6 | AJ10: 5.86 | AK10: 5.854467 | AL10: -0.00994 | AM10: -0.001696 | AN10: 0.036957 | AO10: 0.039931 | AP10: 0.08048 | AQ10: 0.953 | AR10: 0
B11: y_bmi | C11: 0.0284 | D11: 0.024145 | E11: -0.00427 | F11: -0.15031 | G11: 0.028681 | H11: 0.031244 | I11: 0.089373 | J11: 0.978 | K11: 0 | M11: y_bmi | N11: 0.068 | O11: 0.033685 | P11: -0.03435 | Q11: -0.5049 | R11: 0.028248 | S11: 0.031287 | T11: 0.10755 | U11: 0.859 | V11: 0 | X11: y_bmi | Y11: 0.03 | Z11: 0.024145 | AA11: -0.00427 | AB11: -0.15031 | AC11: 0.028681 | AD11: 0.031244 | AE11: 0.089373 | AF11: 0.978 | AG11: 0 | AI11: y_bmi | AJ11: 0.03 | AK11: 0.033685 | AL11: 0.00158 | AM11: 0.049112 | AN11: 0.028248 | AO11: 0.031287 | AP11: 0.10755 | AQ11: 0.976 | AR11: 0
A13: [NO MI] | B13: [PROC GENMOD][IND CORR][NO MI][Logistic RR][bghhsub_s2] | M13: [PROC GENMOD][EXCH CORR][NO MI][Logistic RR][bghhsub_s2] | X13: [PROC GENMOD][IND CORR][NO MI][Logistic RR][bghhsub_s2][SUDAAN TRUE] | AI13: [PROC GENMOD][EXCH CORR][NO MI][Logistic RR][bghhsub_s2][SUDAAN TRUE] | AS13: [NO MI] | AU13: 2
B14: Effect | C14: True Value | D14: Estimate | E14: Empirical Bias | F14: Relative Bias | G14: Empirical SE | H14: Estimated SE | I14: Relative SE difference | J14: Coverage | K14: P(reject H0) | M14: Effect | N14: True Value | O14: Estimate | P14: Empirical Bias | Q14: Relative Bias | R14: Empirical SE | S14: Estimated SE | T14: Relative SE difference | U14: Coverage | V14: P(reject H0) | X14: Effect | Y14: True Value | Z14: Estimate | AA14: Empirical Bias | AB14: Relative Bias | AC14: Empirical SE | AD14: Estimated SE | AE14: Relative SE difference | AF14: Coverage | AG14: P(reject H0) | AI14: Effect | AJ14: True Value | AK14: Estimate | AL14: Empirical Bias | AM14: Relative Bias | AN14: Empirical SE | AO14: Estimated SE | AP14: Relative SE difference | AQ14: Coverage | AR14: P(reject H0)
B15: Intercept | C15: 107.0774 | D15: 107.641 | E15: 0.5636 | F15: 0.00526 | G15: 1.9875 | H15: 2.0816 | I15: 0.047347 | J15: 0.957 | K15: 1 | M15: Intercept | N15: 105.9799 | O15: 109.2269 | P15: 3.24693 | Q15: 0.03064 | R15: 1.9894 | S15: 2.0182 | T15: 0.014509 | U15: 0.635 | V15: 1 | X15: Intercept | Y15: 107.08 | Z15: 107.641 | AA15: 0.5636 | AB15: 0.00526 | AC15: 1.9875 | AD15: 2.0816 | AE15: 0.047347 | AF15: 0.957 | AG15: 1 | AI15: Intercept | AJ15: 106.81 | AK15: 109.2269 | AL15: 2.41441 | AM15: 0.0226 | AN15: 1.9894 | AO15: 2.0182 | AP15: 0.014509 | AQ15: 0.777 | AR15: 1 | AU15: V1 weights in fitting step
B16: age_strat_new | C16: -4.7686 | D16: -4.6211 | E16: 0.14757 | F16: -0.03095 | G16: 0.7558 | H16: 0.7848 | I16: 0.03843 | J16: 0.953 | K16: 1 | M16: age_strat_new | N16: -5.1666 | O16: -4.617 | P16: 0.54961 | Q16: -0.10638 | R16: 0.8009 | S16: 0.8076 | T16: 0.008368 | U16: 0.902 | V16: 0.998 | X16: age_strat_new | Y16: -4.77 | Z16: -4.6211 | AA16: 0.14757 | AB16: -0.03095 | AC16: 0.7558 | AD16: 0.7848 | AE16: 0.03843 | AF16: 0.953 | AG16: 1 | AI16: age_strat_new | AJ16: -4.8 | AK16: -4.617 | AL16: 0.18232 | AM16: -0.03799 | AN16: 0.8009 | AO16: 0.8076 | AP16: 0.008368 | AQ16: 0.952 | AR16: 0.998
B17: x12 | C17: 8.6967 | D17: 7.0959 | E17: -1.60076 | F17: -0.18406 | G17: 0.4684 | H17: 0.4724 | I17: 0.00872 | J17: 0.073 | K17: 1 | M17: x12 | N17: 8.6968 | O17: 6.5931 | P17: -2.10375 | Q17: -0.2419 | R17: 0.5162 | S17: 0.5025 | T17: -0.026558 | U17: 0.018 | V17: 1 | X17: x12 | Y17: 8.7 | Z17: 7.0959 | AA17: -1.60076 | AB17: -0.18406 | AC17: 0.4684 | AD17: 0.4724 | AE17: 0.00872 | AF17: 0.073 | AG17: 1 | AI17: x12 | AJ17: 8.7 | AK17: 6.5931 | AL17: -2.10912 | AM17: -0.24237 | AN17: 0.5162 | AO17: 0.5025 | AP17: -0.026558 | AQ17: 0.018 | AR17: 1
B18: x17 | C18: -1.6103 | D18: -1.7574 | E18: -0.14712 | F18: 0.09137 | G18: 0.473 | H18: 0.5043 | I18: 0.066263 | J18: 0.962 | K18: 0.946 | M18: x17 | N18: -1.5934 | O18: -2.1466 | P18: -0.55313 | Q18: 0.34713 | R18: 0.4878 | S18: 0.5032 | T18: 0.031457 | U18: 0.817 | V18: 0.993 | X18: x17 | Y18: -1.61 | Z18: -1.7574 | AA18: -0.14712 | AB18: 0.09137 | AC18: 0.473 | AD18: 0.5043 | AE18: 0.066263 | AF18: 0.962 | AG18: 0.946 | AI18: x17 | AJ18: -1.58 | AK18: -2.1466 | AL18: -0.56594 | AM18: 0.35805 | AN18: 0.4878 | AO18: 0.5032 | AP18: 0.031457 | AQ18: 0.809 | AR18: 0.993
B19: x18 | C19: -7.9152 | D19: -6.3607 | E19: 1.55448 | F19: -0.19639 | G19: 0.6182 | H19: 0.6091 | I19: -0.014748 | J19: 0.278 | K19: 1 | M19: x18 | N19: -7.9049 | O19: -5.6734 | P19: 2.23152 | Q19: -0.2823 | R19: 0.6657 | S19: 0.6366 | T19: -0.043616 | U19: 0.082 | V19: 1 | X19: x18 | Y19: -7.92 | Z19: -6.3607 | AA19: 1.55448 | AB19: -0.19639 | AC19: 0.6182 | AD19: 0.6091 | AE19: -0.014748 | AF19: 0.278 | AG19: 1 | AI19: x18 | AJ19: -7.78 | AK19: -5.6734 | AL19: 2.10305 | AM19: -0.27044 | AN19: 0.6657 | AO19: 0.6366 | AP19: -0.043616 | AQ19: 0.112 | AR19: 1
B20: x6 | C20: 5.8681 | D20: 5.8629 | E20: -0.00527 | F20: -0.0009 | G20: 0.0421 | H20: 0.0418 | I20: -0.007781 | J20: 0.941 | K20: 1 | M20: x6 | N20: 5.8287 | O20: 5.9097 | P20: 0.08109 | Q20: 0.01391 | R20: 0.0379 | S20: 0.0378 | T20: -0.004139 | U20: 0.43 | V20: 1 | X20: x6 | Y20: 5.87 | Z20: 5.8629 | AA20: -0.00527 | AB20: -0.0009 | AC20: 0.0421 | AD20: 0.0418 | AE20: -0.007781 | AF20: 0.941 | AG20: 1 | AI20: x6 | AJ20: 5.86 | AK20: 5.9097 | AL20: 0.04533 | AM20: 0.00773 | AN20: 0.0379 | AO20: 0.0378 | AP20: -0.004139 | AQ20: 0.77 | AR20: 1
B21: y_bmi | C21: 0.0284 | D21: 0.0385 | E21: 0.01009 | F21: 0.35519 | G21: 0.0259 | H21: 0.0251 | I21: -0.029468 | J21: 0.926 | K21: 0.352 | M21: y_bmi | N21: 0.068 | O21: 0.048 | P21: -0.02003 | Q21: -0.29445 | R21: 0.0222 | S21: 0.0217 | T21: -0.022633 | U21: 0.833 | V21: 0.597 | X21: y_bmi | Y21: 0.03 | Z21: 0.0385 | AA21: 0.01009 | AB21: 0.35519 | AC21: 0.0259 | AD21: 0.0251 | AE21: -0.029468 | AF21: 0.926 | AG21: 0.352 | AI21: y_bmi | AJ21: 0.03 | AK21: 0.048 | AL21: 0.01589 | AM21: 0.49503 | AN21: 0.0222 | AO21: 0.0217 | AP21: -0.022633 | AQ21: 0.881 | AR21: 0.597
AU22: 2.1: use visit-level IPW weights instead of V1 weights
A23: [MI] [NOMISS V3] | B23: [PROC GENMOD][IND CORR][MI][Logistic RR][NOMISS V3][bghhsub_s2] | M23: [PROC GENMOD][EXCH CORR][MI][Logistic RR][NOMISS V3][bghhsub_s2] | X23: [PROC GENMOD][IND CORR][MI][Logistic RR][NOMISS V3][bghhsub_s2][SUDAAN TRUE] | AI23: [PROC GENMOD][EXCH CORR][MI][Logistic RR][NOMISS V3][bghhsub_s2][SUDAAN TRUE] | AS23: [MI] [NOMISS V3]
B24: Effect | C24: True Value | D24: Estimate | E24: Empirical Bias | F24: Relative Bias | G24: Empirical SE | H24: Estimated SE | I24: Relative SE difference | J24: Coverage | K24: P(reject H0) | M24: Effect | N24: True Value | O24: Estimate | P24: Empirical Bias | Q24: Relative Bias | R24: Empirical SE | S24: Estimated SE | T24: Relative SE difference | U24: Coverage | V24: P(reject H0) | X24: Effect | Y24: True Value | Z24: Estimate | AA24: Empirical Bias | AB24: Relative Bias | AC24: Empirical SE | AD24: Estimated SE | AE24: Relative SE difference | AF24: Coverage | AG24: P(reject H0) | AI24: Effect | AJ24: True Value | AK24: Estimate | AL24: Empirical Bias | AM24: Relative Bias | AN24: Empirical SE | AO24: Estimated SE | AP24: Relative SE difference | AQ24: Coverage | AR24: P(reject H0)
B25: Intercept | C25: 107.0774 | D25: 102.95711 | E25: -4.12029 | F25: -0.03848 | G25: 2.455818 | H25: 2.587164 | I25: 0.053484 | J25: 0.638 | K25: 0 | M25: Intercept | N25: 105.9799 | O25: 102.98236 | P25: -2.99757 | Q25: -0.02828 | R25: 2.651135 | S25: 2.748955 | T25: 0.036897 | U25: 0.805 | V25: 0 | X25: Intercept | Y25: 107.08 | Z25: 102.95711 | AA25: -4.12029 | AB25: -0.03848 | AC25: 2.455818 | AD25: 2.587164 | AE25: 0.053484 | AF25: 0.638 | AG25: 0 | AI25: Intercept | AJ25: 106.81 | AK25: 102.98236 | AL25: -3.83009 | AM25: -0.03586 | AN25: 2.651135 | AO25: 2.748955 | AP25: 0.036897 | AQ25: 0.703 | AR25: 0
B26: age_strat_new | C26: -4.7686 | D26: -4.218512 | E26: 0.55013 | F26: -0.11536 | G26: 0.989477 | H26: 1.023644 | I26: 0.034531 | J26: 0.929 | K26: 0 | M26: age_strat_new | N26: -5.1666 | O26: -4.160372 | P26: 1.0062 | Q26: -0.19475 | R26: 1.124162 | S26: 1.145951 | T26: 0.019383 | U26: 0.863 | V26: 0 | X26: age_strat_new | Y26: -4.77 | Z26: -4.218512 | AA26: 0.55013 | AB26: -0.11536 | AC26: 0.989477 | AD26: 1.023644 | AE26: 0.034531 | AF26: 0.929 | AG26: 0 | AI26: age_strat_new | AJ26: -4.8 | AK26: -4.160372 | AL26: 0.63891 | AM26: -0.13313 | AN26: 1.124162 | AO26: 1.145951 | AP26: 0.019383 | AQ26: 0.92 | AR26: 0
B27: x12 | C27: 8.6967 | D27: 8.547964 | E27: -0.14873 | F27: -0.0171 | G27: 0.560568 | H27: 0.561887 | I27: 0.002354 | J27: 0.948 | K27: 0 | M27: x12 | N27: 8.6968 | O27: 8.577834 | P27: -0.119 | Q27: -0.01368 | R27: 0.677665 | S27: 0.657046 | T27: -0.030426 | U27: 0.942 | V27: 0 | X27: x12 | Y27: 8.7 | Z27: 8.547964 | AA27: -0.14873 | AB27: -0.0171 | AC27: 0.560568 | AD27: 0.561887 | AE27: 0.002354 | AF27: 0.948 | AG27: 0 | AI27: x12 | AJ27: 8.7 | AK27: 8.577834 | AL27: -0.12437 | AM27: -0.01429 | AN27: 0.677665 | AO27: 0.657046 | AP27: -0.030426 | AQ27: 0.941 | AR27: 0
B28: x17 | C28: -1.6103 | D28: -1.04567 | E28: 0.56462 | F28: -0.35063 | G28: 0.571257 | H28: 0.600298 | I28: 0.050837 | J28: 0.856 | K28: 0 | M28: x17 | N28: -1.5934 | O28: -1.147678 | P28: 0.44576 | Q28: -0.27975 | R28: 0.627665 | S28: 0.637036 | T28: 0.014931 | U28: 0.89 | V28: 0 | X28: x17 | Y28: -1.61 | Z28: -1.04567 | AA28: 0.56462 | AB28: -0.35063 | AC28: 0.571257 | AD28: 0.600298 | AE28: 0.050837 | AF28: 0.856 | AG28: 0 | AI28: x17 | AJ28: -1.58 | AK28: -1.147678 | AL28: 0.43295 | AM28: -0.27391 | AN28: 0.627665 | AO28: 0.637036 | AP28: 0.014931 | AQ28: 0.893 | AR28: 0
B29: x18 | C29: -7.9152 | D29: -8.206118 | E29: -0.29094 | F29: 0.03676 | G29: 0.785912 | H29: 0.776122 | I29: -0.012458 | J29: 0.927 | K29: 0 | M29: x18 | N29: -7.9049 | O29: -8.118057 | P29: -0.21316 | Q29: 0.02697 | R29: 0.942763 | S29: 0.906104 | T29: -0.038884 | U29: 0.93 | V29: 0 | X29: x18 | Y29: -7.92 | Z29: -8.206118 | AA29: -0.29094 | AB29: 0.03676 | AC29: 0.785912 | AD29: 0.776122 | AE29: -0.012458 | AF29: 0.927 | AG29: 0 | AI29: x18 | AJ29: -7.78 | AK29: -8.118057 | AL29: -0.34163 | AM29: 0.04393 | AN29: 0.942763 | AO29: 0.906104 | AP29: -0.038884 | AQ29: 0.915 | AR29: 0
B30: x6 | C30: 5.8681 | D30: 6.048017 | E30: 0.17988 | F30: 0.03065 | G30: 0.056091 | H30: 0.05741 | I30: 0.023526 | J30: 0.134 | K30: 0 | M30: x6 | N30: 5.8287 | O30: 6.034798 | P30: 0.20614 | Q30: 0.03537 | R30: 0.058563 | S30: 0.06123 | T30: 0.045537 | U30: 0.122 | V30: 0 | X30: x6 | Y30: 5.87 | Z30: 6.048017 | AA30: 0.17988 | AB30: 0.03065 | AC30: 0.056091 | AD30: 0.05741 | AE30: 0.023526 | AF30: 0.134 | AG30: 0 | AI30: x6 | AJ30: 5.86 | AK30: 6.034798 | AL30: 0.17039 | AM30: 0.02905 | AN30: 0.058563 | AO30: 0.06123 | AP30: 0.045537 | AQ30: 0.21 | AR30: 0
B31: y_bmi | C31: 0.0284 | D31: 0.018427 | E31: -0.00999 | F31: -0.35154 | G31: 0.042598 | H31: 0.044226 | I31: 0.038208 | J31: 0.975 | K31: 0 | M31: y_bmi | N31: 0.068 | O31: 0.030219 | P31: -0.03782 | Q31: -0.55584 | R31: 0.046173 | S31: 0.047756 | T31: 0.034274 | U31: 0.919 | V31: 0 | X31: y_bmi | Y31: 0.03 | Z31: 0.018427 | AA31: -0.00999 | AB31: -0.35154 | AC31: 0.042598 | AD31: 0.044226 | AE31: 0.038208 | AF31: 0.975 | AG31: 0 | AI31: y_bmi | AJ31: 0.03 | AK31: 0.030219 | AL31: -0.00189 | AM31: -0.05883 | AN31: 0.046173 | AO31: 0.047756 | AP31: 0.034274 | AQ31: 0.979 | AR31: 0
A33: [MI] [NOMISS V3] | B33: [PROC GENMOD][IND CORR][MI][Logistic RR][NOMISS V3][bghhsub_s2_v3_nr] | M33: [PROC GENMOD][EXCH CORR][MI][Logistic RR][NOMISS V3][bghhsub_s2_v3_nr] | X33: [PROC GENMOD][IND CORR][MI][Logistic RR][NOMISS V3][bghhsub_s2_v3_nr][SUDAAN TRUE] | AI33: [PROC GENMOD][EXCH CORR][MI][Logistic RR][NOMISS V3][bghhsub_s2_v3_nr][SUDAAN TRUE] | AS33: [MI] [NOMISS V3]
B34: Effect | C34: True Value | D34: Estimate | E34: Empirical Bias | F34: Relative Bias | G34: Empirical SE | H34: Estimated SE | I34: Relative SE difference | J34: Coverage | K34: P(reject H0) | M34: Effect | N34: True Value | O34: Estimate | P34: Empirical Bias | Q34: Relative Bias | R34: Empirical SE | S34: Estimated SE | T34: Relative SE difference | U34: Coverage | V34: P(reject H0) | X34: Effect | Y34: True Value | Z34: Estimate | AA34: Empirical Bias | AB34: Relative Bias | AC34: Empirical SE | AD34: Estimated SE | AE34: Relative SE difference | AF34: Coverage | AG34: P(reject H0) | AI34: Effect | AJ34: True Value | AK34: Estimate | AL34: Empirical Bias | AM34: Relative Bias | AN34: Empirical SE | AO34: Estimated SE | AP34: Relative SE difference | AQ34: Coverage | AR34: P(reject H0) | AU34: 3
B35: Intercept | C35: 107.0774 | D35: 107.62566 | E35: 0.54825 | F35: 0.00512 | G35: 5.474822 | H35: 6.239739 | I35: 0.13972 | J35: 0.964 | K35: 0 | M35: Intercept | N35: 105.9799 | O35: 108.1874 | P35: 2.20746 | Q35: 0.02083 | R35: 6.582481 | S35: 7.564087 | T35: 0.14912 | U35: 0.935 | V35: 0 | X35: Intercept | Y35: 107.08 | Z35: 107.62566 | AA35: 0.54825 | AB35: 0.00512 | AC35: 5.474822 | AD35: 6.239739 | AE35: 0.13972 | AF35: 0.964 | AG35: 0 | AI35: Intercept | AJ35: 106.81 | AK35: 108.1874 | AL35: 1.37494 | AM35: 0.01287 | AN35: 6.582481 | AO35: 7.564087 | AP35: 0.14912 | AQ35: 0.949 | AR35: 0
B36: age_strat_new | C36: -4.7686 | D36: -4.952623 | E36: -0.18398 | F36: 0.03858 | G36: 2.262265 | H36: 2.487745 | I36: 0.09967 | J36: 0.977 | K36: 0 | M36: age_strat_new | N36: -5.1666 | O36: -4.620186 | P36: 0.54639 | Q36: -0.10575 | R36: 2.555004 | S36: 2.865338 | T36: 0.12146 | U36: 0.943 | V36: 0 | X36: age_strat_new | Y36: -4.77 | Z36: -4.952623 | AA36: -0.18398 | AB36: 0.03858 | AC36: 2.262265 | AD36: 2.487745 | AE36: 0.09967 | AF36: 0.977 | AG36: 0 | AI36: age_strat_new | AJ36: -4.8 | AK36: -4.620186 | AL36: 0.1791 | AM36: -0.03732 | AN36: 2.555004 | AO36: 2.865338 | AP36: 0.12146 | AQ36: 0.954 | AR36: 0 | AU36: V3 sample + MI (with v1, v2, v3, IPW weights) + v3 IPW weights in fitting
B37: x12 | C37: 8.6967 | D37: 8.685749 | E37: -0.01095 | F37: -0.00126 | G37: 1.063562 | H37: 1.046513 | I37: -0.01603 | J37: 0.949 | K37: 0 | M37: x12 | N37: 8.6968 | O37: 8.696905 | P37: 7e-05 | Q37: 1e-05 | R37: 1.113756 | S37: 1.087044 | T37: -0.02398 | U37: 0.952 | V37: 0 | X37: x12 | Y37: 8.7 | Z37: 8.685749 | AA37: -0.01095 | AB37: -0.00126 | AC37: 1.063562 | AD37: 1.046513 | AE37: -0.01603 | AF37: 0.949 | AG37: 0 | AI37: x12 | AJ37: 8.7 | AK37: 8.696905 | AL37: -0.0053 | AM37: -0.00061 | AN37: 1.113756 | AO37: 1.087044 | AP37: -0.02398 | AQ37: 0.953 | AR37: 0
B38: x17 | C38: -1.6103 | D38: -1.304653 | E38: 0.30564 | F38: -0.1898 | G38: 1.196427 | H38: 1.183343 | I38: -0.01094 | J38: 0.959 | K38: 0 | M38: x17 | N38: -1.5934 | O38: -1.459477 | P38: 0.13396 | Q38: -0.08407 | R38: 1.515721 | S38: 1.492094 | T38: -0.01559 | U38: 0.954 | V38: 0 | X38: x17 | Y38: -1.61 | Z38: -1.304653 | AA38: 0.30564 | AB38: -0.1898 | AC38: 1.196427 | AD38: 1.183343 | AE38: -0.01094 | AF38: 0.959 | AG38: 0 | AI38: x17 | AJ38: -1.58 | AK38: -1.459477 | AL38: 0.12115 | AM38: -0.07665 | AN38: 1.515721 | AO38: 1.492094 | AP38: -0.01559 | AQ38: 0.954 | AR38: 0
B39: x18 | C39: -7.9152 | D39: -7.698441 | E39: 0.21673 | F39: -0.02738 | G39: 1.398517 | H39: 1.398215 | I39: -0.00022 | J39: 0.95 | K39: 0 | M39: x18 | N39: -7.9049 | O39: -7.660651 | P39: 0.24424 | Q39: -0.0309 | R39: 1.504315 | S39: 1.452199 | T39: -0.03464 | U39: 0.947 | V39: 0 | X39: x18 | Y39: -7.92 | Z39: -7.698441 | AA39: 0.21673 | AB39: -0.02738 | AC39: 1.398517 | AD39: 1.398215 | AE39: -0.00022 | AF39: 0.95 | AG39: 0 | AI39: x18 | AJ39: -7.78 | AK39: -7.660651 | AL39: 0.11578 | AM39: -0.01489 | AN39: 1.504315 | AO39: 1.452199 | AP39: -0.03464 | AQ39: 0.95 | AR39: 0
B40: x6 | C40: 5.8681 | D40: 5.924767 | E40: 0.05663 | F40: 0.00965 | G40: 0.165074 | H40: 0.188522 | I40: 0.14205 | J40: 0.979 | K40: 0 | M40: x6 | N40: 5.8287 | O40: 5.914217 | P40: 0.08556 | Q40: 0.01468 | R40: 0.179016 | S40: 0.210266 | T40: 0.17456 | U40: 0.974 | V40: 0 | X40: x6 | Y40: 5.87 | Z40: 5.924767 | AA40: 0.05663 | AB40: 0.00965 | AC40: 0.165074 | AD40: 0.188522 | AE40: 0.14205 | AF40: 0.979 | AG40: 0 | AI40: x6 | AJ40: 5.86 | AK40: 5.914217 | AL40: 0.04981 | AM40: 0.00849 | AN40: 0.179016 | AO40: 0.210266 | AP40: 0.17456 | AQ40: 0.985 | AR40: 0
B41: y_bmi | C41: 0.0284 | D41: -0.025503 | E41: -0.05392 | F41: -1.89745 | G41: 0.153357 | H41: 0.1747 | I41: 0.13918 | J41: 0.983 | K41: 0 | M41: y_bmi | N41: 0.068 | O41: -0.01443 | P41: -0.08247 | Q41: -1.21209 | R41: 0.171187 | S41: 0.200857 | T41: 0.17332 | U41: 0.973 | V41: 0 | X41: y_bmi | Y41: 0.03 | Z41: -0.025503 | AA41: -0.05392 | AB41: -1.89745 | AC41: 0.153357 | AD41: 0.1747 | AE41: 0.13918 | AF41: 0.983 | AG41: 0 | AI41: y_bmi | AJ41: 0.03 | AK41: -0.01443 | AL41: -0.04654 | AM41: -1.4494 | AN41: 0.171187 | AO41: 0.200857 | AP41: 0.17332 | AQ41: 0.987 | AR41: 0
A43: [NO MI] [NOMISS V3] | B43: [PROC GENMOD][IND CORR][NO MI][Logistic RR][NOMISS V3][bghhsub_s2_v3_nr] | M43: [PROC GENMOD][EXCH CORR][NO MI][Logistic RR][NOMISS V3][bghhsub_s2_v3_nr] | X43: [PROC GENMOD][IND CORR][NO MI][Logistic RR][NOMISS V3][bghhsub_s2_v3_nr][SUDAAN TRUE] | AI43: [PROC GENMOD][EXCH CORR][NO MI][Logistic RR][NOMISS V3][bghhsub_s2_v3_nr][SUDAAN TRUE] | AS43: [NO MI] [NOMISS V3]
...

Sheet Method Codes
A1: Method | B1: corr | C1: mitype | D1: mi | E1: v3only | F1: RR | G1: proc | H1: suffix | I1: Spec
A2: Method 1 | B2: IND | C2: cont | D2: 1 | E2: 0 | F2: RR_glm | H2: 1A | I2: [1][PROC GENMOD][IND CORR][MI][RR_glm][bghhsub_s2]
A3: Method 1 | B3: IND | C3: cont | D3: 1 | E3: 0 | F3: RR_NRadj | H3: 1B | I3: [1][PROC GENMOD][IND CORR][MI][RR_NRadj][bghhsub_s2]
A4: Method 1 | B4: IND | C4: cont | D4: 1 | E4: 0 | F4: RR_glm_strat | H4: 1C | I4: [1][PROC GENMOD][IND CORR][MI][RR_glm_strat][bghhsub_s2]
A5: Method 1 | B5: IND | C5: cont | D5: 1 | E5: 0 | F5: RR_NRadj_strat | H5: 1D | I5: [1][PROC GENMOD][IND CORR][MI][RR_NRadj_strat][bghhsub_s2]
A6: Method 1 | B6: IND | C6: bin | D6: 1 | E6: 0 | F6: RR_glm | H6: 1E | I6: [1][PROC GENMOD][BINARY][IND CORR][MI][RR_glm][bghhsub_s2]
A7: Method 1 | B7: IND | C7: bin | D7: 1 | E7: 0 | F7: RR_NRadj | H7: 1F | I7: [1][PROC GENMOD][BINARY][IND CORR][MI][RR_NRadj][bghhsub_s2]
A8: Method 1 | B8: IND | C8: bin | D8: 1 | E8: 0 | F8: RR_glm_strat | H8: 1G | I8: [1][PROC GENMOD][BINARY][IND CORR][MI][RR_glm_strat][bghhsub_s2]
A9: Method 1 | B9: IND | C9: bin | D9: 1 | E9: 0 | F9: RR_NRadj_strat | H9: 1H | I9: [1][PROC GENMOD][BINARY][IND CORR][MI][RR_NRadj_strat][bghhsub_s2]
A10: Method 2 | B10: IND | C10: cont | D10: 0 | E10: 0 | F10: RR_glm | G10: genmod | H10: 2A | I10: [2][PROC GENMOD][IND CORR][NO MI][RR_glm][bghhsub_s2]
A11: Method 2 | B11: IND | C11: cont | D11: 0 | E11: 0 | F11: RR_NRadj | G11: genmod | H11: 2B | I11: [2][PROC GENMOD][IND CORR][NO MI][RR_NRadj][bghhsub_s2]
A12: Method 2 | B12: IND | C12: cont | D12: 0 | E12: 0 | F12: RR_glm | G12: gee | H12: 2C | I12: [2][PROC GEE][IND CORR][NO MI][RR_glm][bghhsub_s2]
A13: Method 2 | B13: IND | C13: cont | D13: 0 | E13: 0 | F13: RR_NRadj | G13: gee | H13: 2D | I13: [2][PROC GEE][IND CORR][NO MI][RR_NRadj][bghhsub_s2]
A14: Method 2 | B14: IND | C14: cont | D14: 0 | E14: 0 | F14: RR_glm_strat | G14: genmod | H14: 2E | I14: [2][PROC GENMOD][IND CORR][NO MI][RR_glm_strat][bghhsub_s2]
A15: Method 2 | B15: IND | C15: cont | D15: 0 | E15: 0 | F15: RR_NRadj_strat | G15: genmod | H15: 2F | I15: [2][PROC GENMOD][IND CORR][NO MI][RR_NRadj_strat][bghhsub_s2]
A16: Method 2 | B16: IND | C16: cont | D16: 0 | E16: 0 | F16: RR_glm_strat | G16: gee | H16: 2G | I16: [2][PROC GEE][IND CORR][NO MI][RR_glm_strat][bghhsub_s2]
A17: Method 2 | B17: IND | C17: cont | D17: 0 | E17: 0 | F17: RR_NRadj_strat | G17: gee | H17: 2H | I17: [2][PROC GEE][IND CORR][NO MI][RR_NRadj_strat][bghhsub_s2]
A18: Method 2 | B18: IND | C18: bin | D18: 0 | E18: 0 | F18: RR_glm | G18: genmod | H18: 2I | I18: [2][PROC GENMOD][BINARY][IND CORR][NO MI][RR_glm][bghhsub_s2]
A19: Method 2 | B19: IND | C19: bin | D19: 0 | E19: 0 | F19: RR_NRadj | G19: genmod | H19: 2J | I19: [2][PROC GENMOD][BINARY][IND CORR][NO MI][RR_NRadj][bghhsub_s2]
A20: Method 2 | B20: IND | C20: bin | D20: 0 | E20: 0 | F20: RR_glm | G20: gee | H20: 2K | I20: [2][PROC GEE][IND CORR][NO MI][RR_glm][bghhsub_s2]
A21: Method 2 | B21: IND | C21: bin | D21: 0 | E21: 0 | F21: RR_NRadj | G21: gee | H21: 2L | I21: [2][PROC GEE][IND CORR][NO MI][RR_NRadj][bghhsub_s2]
... A25: Method 2 | B25: IND | C25: bin | D25: 0 | E25: 0 | F25: RR_NRadj_strat | G25: gee | H25: 2P | I25: [2][PROC GEE][IND CORR][NO MI][RR_NRadj_strat][bghhsub_s2]
A26: Method 3 | B26: IND | C26: cont | D26: 1 | E26: 1 | F26: RR_glm | H26: 3A | I26: [3][PROC GENMOD][IND CORR][MI][RR_glm][NOMISS V3][bghhsub_s2_v3_nr]
A27: Method 3 | B27: IND | C27: cont | D27: 1 | E27: 1 | F27: RR_NRadj | H27: 3B | I27: [3][PROC GENMOD][IND CORR][MI][RR_NRadj][NOMISS V3][bghhsub_s2_v3_nr]
A28: Method 3 | B28: IND | C28: cont | D28: 1 | E28: 1 | F28: RR_glm_strat | H28: 3C | I28: [3][PROC GENMOD][IND CORR][MI][RR_glm_strat][NOMISS V3][bghhsub_s2_v3_nr]
A29: Method 3 | B29: IND | C29: cont | D29: 1 | E29: 1 | F29: RR_NRadj_strat | H29: 3D | I29: [3][PROC GENMOD][IND CORR][MI][RR_NRadj_strat][NOMISS V3][bghhsub_s2_v3_nr]
A30: Method 3 | B30: IND | C30: bin | D30: 1 | E30: 1 | F30: RR_glm | H30: 3E | I30: [3][PROC GENMOD][BINARY][IND CORR][MI][RR_glm][NOMISS V3][bghhsub_s2_v3_nr]
A31: Method 3 | B31: IND | C31: bin | D31: 1 | E31: 1 | F31: RR_NRadj | H31: 3F | I31: [3][PROC GENMOD][BINARY][IND CORR][MI][RR_NRadj][NOMISS V3][bghhsub_s2_v3_nr]
A32: Method 3 | B32: IND | C32: bin | D32: 1 | E32: 1 | F32: RR_glm_strat | H32: 3G | I32: [3][PROC GENMOD][BINARY][IND CORR][MI][RR_glm_strat][NOMISS V3][bghhsub_s2_v3_nr]
A33: Method 3 | B33: IND | C33: bin | D33: 1 | E33: 1 | F33: RR_NRadj_strat | H33: 3H | I33: [3][PROC GENMOD][BINARY][IND CORR][MI][RR_NRadj_strat][NOMISS V3][bghhsub_s2_v3_nr]
A34: Method 4 | B34: IND | C34: cont | D34: 0 | E34: 1 | F34: RR_glm | G34: genmod | H34: 4A | I34: [4][PROC GENMOD][IND CORR][NO MI][RR_glm][NOMISS V3][bghhsub_s2_v3_nr]
A35: Method 4 | B35: IND | C35: cont | D35: 0 | E35: 1 | F35: RR_NRadj | G35: genmod | H35: 4B | I35: [4][PROC GENMOD][IND CORR][NO MI][RR_NRadj][NOMISS V3][bghhsub_s2_v3_nr]
A36: Method 4 | B36: IND | C36: cont | D36: 0 | E36: 1 | F36: RR_glm | G36: gee | H36: 4C | I36: [4][PROC GEE][IND CORR][NO MI][RR_glm][NOMISS V3][bghhsub_s2_v3_nr]
A37: Method 4 | B37: IND | C37: cont | D37: 0 | E37: 1 | F37: RR_NRadj | G37: gee | H37: 4D | I37: [4][PROC GEE][IND CORR][NO MI][RR_NRadj][NOMISS V3][bghhsub_s2_v3_nr]
A38: Method 4 | B38: IND | C38: cont | D38: 0 | E38: 1 | F38: RR_glm_strat | G38: genmod | H38: 4E | I38: [4][PROC GENMOD][IND CORR][NO MI][RR_glm_strat][NOMISS V3][bghhsub_s2_v3_nr]
A39: Method 4 | B39: IND | C39: cont | D39: 0 | E39: 1 | F39: RR_NRadj_strat | G39: genmod | H39: 4F | I39: [4][PROC GENMOD][IND CORR][NO MI][RR_NRadj_strat][NOMISS V3][bghhsub_s2_v3_nr]
A40: Method 4 | B40: IND | C40: cont | D40: 0 | E40: 1 | F40: RR_glm_strat | G40: gee | H40: 4G | I40: [4][PROC GEE][IND CORR][NO MI][RR_glm_strat][NOMISS V3][bghhsub_s2_v3_nr]
A41: Method 4 | B41: IND | C41: cont | D41: 0 | E41: 1 | F41: RR_NRadj_strat | G41: gee | H41: 4H | I41: [4][PROC GEE][IND CORR][NO MI][RR_NRadj_strat][NOMISS V3][bghhsub_s2_v3_nr]
A42: Method 4 | B42: IND | C42: bin | D42: 0 | E42: 1 | F42: RR_glm | G42: genmod | H42: 4I | I42: [4][PROC GENMOD][BINARY][IND CORR][NO MI][RR_glm][NOMISS V3][bghhsub_s2_v3_nr]
A43: Method 4 | B43: IND | C43: bin | D43: 0 | E43: 1 | F43: RR_NRadj | G43: genmod | H43: 4J | I43: [4][PROC GENMOD][BINARY][IND CORR][NO MI][RR_NRadj][NOMISS V3][bghhsub_s2_v3_nr]
...

Sheet Batch Output
A1: group | B1: suffix | C1: Parm | D1: _TYPE_ | E1: _FREQ_ | F1: True Value | G1: Estimate | H1: Empirical Bias | I1: Relative Bias | J1: Empirical SE | K1: Estimated SE | L1: Relative SE difference | M1: Coverage | N1: P(reject H0)
A2: EXCH | B2: 1A | C2: Intercept | D2: 1 | E2: 1000 | F2: 106.8125 | G2: 107.10514 | H2: 0.29268223 | I2: 1.393985 | J2: 1.400711 | K2: 0.004824706 | L2: 0.0027401508 | M2: 0.944 | N2: 0
A3: EXCH | B3: 1A | C3: age_strat_new | D3: 1 | E3: 1000 | F3: -4.7993 | G3: -4.781034 | H3: 0.018247555 | I3: 0.542475 | J3: 0.565387 | K3: 0.042237351 | L3: -0.003802143 | M3: 0.961 | N3: 0
A4: EXCH | B4: 1A | C4: x12 | D4: 1 | E4: 1000 | F4: 8.7022 | G4: 8.704283 | H4: 0.0020758462 | I4: 0.343029 | J4: 0.343674 | K4: 0.001880472 | L4: 0.0002385425 | M4: 0.95 | N4: 0
A5: EXCH | B5: 1A | C5: x17 | D5: 1 | E5: 1000 | F5: -1.5806 | G5: -1.677658 | H5: -0.097032127 | I5: 0.350409 | J5: 0.34932 | K5: -0.003107178 | L5: 0.06138842 | M5: 0.938 | N5: 0
A6: EXCH | B6: 1A | C6: x18 | D6: 1 | E6: 1000 | F6: -7.7764 | G6: -7.831825 | H6: -0.055396254 | I6: 0.410945 | J6: 0.425945 | K6: 0.036501604 | L6: 0.0071236109 | M6: 0.954 | N6: 0
A7: EXCH | B7: 1A | C7: x6 | D7: 1 | E7: 1000 | F7: 5.8644 | G7: 5.851821 | H7: -0.012589649 | I7: 0.021341 | J7: 0.022537 | K7: 0.056024711 | L7: -0.002146788 | M7: 0.926 | N7: 0
A8: EXCH | B8: 1A | C8: y_bmi | D8: 1 | E8: 1000 | F8: 0.0321 | G8: 0.038078 | H8: 0.0059693899 | I8: 0.013713 | J8: 0.01579 | K8: 0.15143202 | L8: 0.1859137 | M8: 0.964 | N8: 0
A9: EXCH | B9: 1B | C9: Intercept | D9: 1 | E9: 1000 | F9: 106.8125 | G9: 107.15691 | H9: 0.3444517 | I9: 1.393354 | J9: 1.397678 | K9: 0.003103648 | L9: 0.003224827 | M9: 0.942 | N9: 0
A10: EXCH | B10: 1B | C10: age_strat_new | D10: 1 | E10: 1000 | F10: -4.7993 | G10: -4.701927 | H10: 0.097355071 | I10: 0.542194 | J10: 0.564309 | K10: 0.040786965 | L10: -0.020285341 | M10: 0.955 | N10: 0
A11: EXCH | B11: 1B | C11: x12 | D11: 1 | E11: 1000 | F11: 8.7022 | G11: 8.698968 | H11: -0.003239316 | I11: 0.341904 | J11: 0.343353 | K11: 0.0042391175 | L11: -0.000372241 | M11: 0.948 | N11: 0
A12: EXCH | B12: 1B | C12: x17 | D12: 1 | E12: 1000 | F12: -1.5806 | G12: -1.730137 | H12: -0.14951122 | I12: 0.349368 | J12: 0.348593 | K12: -0.002217163 | L12: 0.094589882 | M12: 0.926 | N12: 0
A13: EXCH | B13: 1B | C13: x18 | D13: 1 | E13: 1000 | F13: -7.7764 | G13: -7.847447 | H13: -0.071018275 | I13: 0.409615 | J13: 0.425323 | K13: 0.038348612 | L13: 0.0091325048 | M13: 0.954 | N13: 0
... A841: IND | B841: 6S | C841: y_bmi | D841: 1 | E841: 880 | F841: -0.0007 | G841: -0.000768 | H841: -5.9838e-05 | I841: 0.002565 | J841: 0.002459 | K841: -0.041354826 | L841: 0.084551779 | M841: 0.94204545 | N841: 0.0625

Sheet Coverages (RR_glm)
B1: SAMPLEMISS_1 - SAMPLEMISS_1000 | X1: SUDAAN-Based True Values (SAMPLEMISS_1 - SAMPLEMISS_1000)
B2: [IND CORR][GEE True] | M2: [EXCH CORR][SUDAAN TRUE] | X2: [IND CORR] | AI2: [EXCH CORR]
A3: [MI] | B3: [1][PROC GENMOD][IND CORR][MI][RR_glm][bghhsub_s2] | J3: =INDEX('Method Codes'!$B:$B, MATCH(B3, 'Method Codes'!$I:$I,0)) -> IND | K3: =INDEX('Method Codes'!$H:$H, MATCH(B3, 'Method Codes'!$I:$I,0)) -> 1A | M3: [1][PROC GENMOD][EXCH CORR][MI][RR_glm][bghhsub_s2] | U3: =INDEX('Method Codes'!$B:$B, MATCH(M3, 'Method Codes'!$I:$I,0)) -> EXCH | V3: =INDEX('Method Codes'!$H:$H, MATCH(M3, 'Method Codes'!$I:$I,0)) -> 1A | X3: [1][PROC GENMOD][IND CORR][MI][RR_glm][bghhsub_s2][SUDAAN TRUE] | AI3: [1][PROC GENMOD][EXCH CORR][MI][RR_glm][bghhsub_s2][SUDAAN TRUE] | AS3: [MI] | AU3: 1
B4: Effect | C4: True Value | D4: Estimate | E4: Empirical Bias | F4: Relative Bias | G4: Empirical SE | H4: Estimated SE | I4: Relative SE difference | J4: Coverage | K4: P(reject H0) | M4: Effect | N4: True Value | O4: Estimate | P4: Empirical Bias | Q4: Relative Bias | R4: Empirical SE | S4: Estimated SE | T4: Relative SE difference | U4: Coverage | V4: P(reject H0) | X4: Effect | Y4: True Value | Z4: Estimate | AA4: Empirical Bias | AB4: Relative Bias | AC4: Empirical SE | AD4: Estimated SE | AE4: Relative SE difference | AF4: Coverage | AG4: P(reject H0) | AI4: Effect | AJ4: True Value | AK4: Estimate | AL4: Empirical Bias | AM4: Relative Bias | AN4: Empirical SE | AO4: Estimated SE | AP4: Relative SE difference | AQ4: Coverage | AR4: P(reject H0) | AU4: IPW weights in MI step
B5: Intercept | C5: {=_xlfn.LET( _xlpm.keyA, J3, _xlpm.keyB, K3, _xlpm.rowKeys, B5:B11, _xlpm.colKeys, C4:K4, _xlpm.data, 'Batch Output'!$C:$Z, _xlpm.rowMatch, _xlfn.XMATCH(_xlpm.rowKeys, 'Batch Output'!$C:$C), _xlpm.colMatch, _xlfn.XMATCH(_xlpm.colKeys, 'Batch Output'!$1:$1), _xlpm.batchMatchRows, _xlfn._xlws.FILTER(ROW('Batch Output'!$A:$A), ('Batch Output'!$A:$A=_xlpm.keyA)*('Batch Output'!$B:$B=_xlpm.keyB)), _xlpm.firstMatchRow, INDEX(_xlpm.batchMatchRows, 1), INDEX(_xlpm.data, _xlpm.rowMatch + _xlpm.firstMatchRow - 2, _xlpm.colMatch - 2) )} -> 107.0774 | D5: 106.95041 | E5: -0.12700068 | F5: 1.36406 | G5: 1.363966 | H5: -6.8991e-05 | I5: -0.001186064 | J5: 0.946 | K5: 0 | M5: Intercept | N5: {=_xlfn.LET( _xlpm.keyA, U3, _xlpm.keyB, V3, _xlpm.rowKeys, M5:M11, _xlpm.colKeys, N4:V4, _xlpm.data, 'Batch Output'!$C:$Z, _xlpm.rowMatch, _xlfn.XMATCH(_xlpm.rowKeys, 'Batch Output'!$C:$C), _xlpm.colMatch, _xlfn.XMATCH(_xlpm.colKeys, 'Batch Output'!$1:$1), _xlpm.batchMatchRows, _xlfn._xlws.FILTER(ROW('Batch Output'!$A:$A), ('Batch Output'!$A:$A=_xlpm.keyA)*('Batch Output'!$B:$B=_xlpm.keyB)), _xlpm.firstMatchRow, INDEX(_xlpm.batchMatchRows, 1), INDEX(_xlpm.data, _xlpm.rowMatch + _xlpm.firstMatchRow - 2, _xlpm.colMatch - 2) )} -> 106.8125 | O5: 107.10514 | P5: 0.29268223 | Q5: 1.393985 | R5: 1.400711 | S5: 0.004824706 | T5: 0.0027401508 | U5: 0.944 | V5: 0 | X5: Intercept | Y5: 107.08 | Z5: 106.97987 | AA5: -0.097538 | AB5: -0.000911 | AC5: 1.35801 | AD5: 1.361959 | AE5: 0.002908 | AF5: 0.951 | AG5: 0 | AI5: Intercept | AJ5: 106.81 | AK5: 107.09889 | AL5: 0.28643 | AM5: 0.00268 | AN5: 1.381398 | AO5: 1.398284 | AP5: 0.01222 | AQ5: 0.948 | AR5: 0 | AU5: V1 weights in fitting step
B6: age_strat_new | C6: -4.7686 | D6: -4.812757 | E6: -0.044115327 | F6: 0.519097 | G6: 0.524635 | H6: 0.010669057 | I6: 0.0092511305 | J6: 0.953 | K6: 0 | M6: age_strat_new | N6: -4.7993 | O6: -4.781034 | P6: 0.018247555 | Q6: 0.542475 | R6: 0.565387 | S6: 0.042237351 | T6: -0.003802143 | U6: 0.961 | V6: 0 | X6: age_strat_new | Y6: -4.77 | Z6: -4.785153 | AA6: -0.016511 | AB6: 0.003462 | AC6: 0.535956 | AD6: 0.524544 | AE6: -0.021292 | AF6: 0.95 | AG6: 0 | AI6: age_strat_new | AJ6: -4.8 | AK6: -4.758175 | AL6: 0.04111 | AM6: -0.00857 | AN6: 0.574804 | AO6: 0.566145 | AP6: -0.01506 | AQ6: 0.945 | AR6: 0
B7: x12 | C7: 8.6967 | D7: 8.705676 | E7: 0.0089774713 | F7: 0.306858 | G7: 0.306333 | H7: -0.001710315 | I7: 0.001032285 | J7: 0.948 | K7: 0 | M7: x12 | N7: 8.7022 | O7: 8.704283 | P7: 0.0020758462 | Q7: 0.343029 | R7: 0.343674 | S7: 0.001880472 | T7: 0.0002385425 | U7: 0.95 | V7: 0 | X7: x12 | Y7: 8.7 | Z7: 8.695153 | AA7: -0.001546 | AB7: -0.000178 | AC7: 0.302934 | AD7: 0.305665 | AE7: 0.009013 | AF7: 0.952 | AG7: 0 | AI7: x12 | AJ7: 8.7 | AK7: 8.719603 | AL7: 0.0174 | AM7: 0.002 | AN7: 0.332203 | AO7: 0.343012 | AP7: 0.03254 | AQ7: 0.961 | AR7: 0 | AU7: IPW weights = base weights / RR
B8: x17 | C8: -1.6103 | D8: -1.55252 | E8: 0.057774858 | F8: 0.337974 | G8: 0.330345 | H8: -0.022573728 | I8: -0.035878441 | J8: 0.946 | K8: 0 | M8: x17 | N8: -1.5806 | O8: -1.677658 | P8: -0.097032127 | Q8: 0.350409 | R8: 0.34932 | S8: -0.003107178 | T8: 0.06138842 | U8: 0.938 | V8: 0 | X8: x17 | Y8: -1.61 | Z8: -1.570868 | AA8: 0.039426 | AB8: -0.024484 | AC8: 0.328737 | AD8: 0.329937 | AE8: 0.003652 | AF8: 0.951 | AG8: 0 | AI8: x17 | AJ8: -1.58 | AK8: -1.689803 | AL8: -0.10918 | AM8: 0.06907 | AN8: 0.348121 | AO8: 0.348888 | AP8: 0.0022 | AQ8: 0.941 | AR8: 0 | AU8: RR = visit-specific missing prob calculated from Logistic
B9: x18 | C9: -7.9152 | D9: -7.917757 | E9: -0.002581097 | F9: 0.369076 | G9: 0.380566 | H9: 0.031132704 | I9: 0.0003260947 | J9: 0.956 | K9: 0 | M9: x18 | N9: -7.7764 | O9: -7.831825 | P9: -0.055396254 | Q9: 0.410945 | R9: 0.425945 | S9: 0.036501604 | T9: 0.0071236109 | U9: 0.954 | V9: 0 | X9: x18 | Y9: -7.92 | Z9: -7.914463 | AA9: 0.000713 | AB9: -9e-05 | AC9: 0.387806 | AD9: 0.380631 | AE9: -0.018501 | AF9: 0.945 | AG9: 0 | AI9: x18 | AJ9: -7.78 | AK9: -7.826184 | AL9: -0.04975 | AM9: 0.0064 | AN9: 0.43863 | AO9: 0.425606 | AP9: -0.02969 | AQ9: 0.95 | AR9: 0
B10: x6 | C10: 5.8681 | D10: 5.865272 | E10: -0.002867287 | F10: 0.023214 | G10: 0.023929 | H10: 0.030792906 | I10: -0.000488619 | J10: 0.953 | K10: 0 | M10: x6 | N10: 5.8644 | O10: 5.851821 | P10: -0.012589649 | Q10: 0.021341 | R10: 0.022537 | S10: 0.056024711 | T10: -0.002146788 | U10: 0.926 | V10: 0 | X10: x6 | Y10: 5.87 | Z10: 5.863666 | AA10: -0.004473 | AB10: -0.000762 | AC10: 0.022694 | AD10: 0.023918 | AE10: 0.053968 | AF10: 0.956 | AG10: 0 | AI10: x6 | AJ10: 5.86 | AK10: 5.850286 | AL10: -0.01412 | AM10: -0.00241 | AN10: 0.020969 | AO10: 0.022528 | AP10: 0.07434 | AQ10: 0.921 | AR10: 0
B11: y_bmi | C11: 0.0284 | D11: 0.025265 | E11: -0.003151738 | F11: 0.016397 | G11: 0.017709 | H11: 0.080011299 | I11: -0.11091216 | J11: 0.957 | K11: 0 | M11: y_bmi | N11: 0.0321 | O11: 0.038078 | P11: 0.0059693899 | Q11: 0.013713 | R11: 0.01579 | S11: 0.15143202 | T11: 0.1859137 | U11: 0.964 | V11: 0 | X11: y_bmi | Y11: 0.03 | Z11: 0.026459 | AA11: -0.001958 | AB11: -0.068901 | AC11: 0.01633 | AD11: 0.017684 | AE11: 0.0829 | AF11: 0.964 | AG11: 0 | AI11: y_bmi | AJ11: 0.03 | AK11: 0.039212 | AL11: 0.0071 | AM11: 0.22124 | AN11: 0.013781 | AO11: 0.015756 | AP11: 0.14336 | AQ11: 0.962 | AR11: 0
A13: [NO MI] | B13: [2][PROC GENMOD][IND CORR][NO MI][RR_glm][bghhsub_s2] | J13: =INDEX('Method Codes'!$B:$B, MATCH(B13, 'Method Codes'!$I:$I,0)) -> IND | K13: =INDEX('Method Codes'!H:H, MATCH(B13, 'Method Codes'!I:I,0)) -> 2A | M13: [2][PROC GENMOD][EXCH CORR][NO MI][RR_glm][bghhsub_s2] | U13: =INDEX('Method Codes'!$B:$B, MATCH(M13, 'Method Codes'!$I:$I,0)) -> EXCH | V13: =INDEX('Method Codes'!$H:$H, MATCH(M13, 'Method Codes'!$I:$I,0)) -> 2A | X13: [2][PROC GENMOD][IND CORR][NO MI][RR_glm][bghhsub_s2][SUDAAN TRUE] | AI13: [2][PROC GENMOD][EXCH CORR][NO MI][RR_glm][bghhsub_s2][SUDAAN TRUE] | AS13: [NO MI] | AU13: 2
B14: Effect | C14: True Value | D14: Estimate | E14: Empirical Bias | F14: Relative Bias | G14: Empirical SE | H14: Estimated SE | I14: Relative SE difference | J14: Coverage | K14: P(reject H0) | M14: Effect | N14: True Value | O14: Estimate | P14: Empirical Bias | Q14: Relative Bias | R14: Empirical SE | S14: Estimated SE | T14: Relative SE difference | U14: Coverage | V14: P(reject H0) | X14: Effect | Y14: True Value | Z14: Estimate | AA14: Empirical Bias | AB14: Relative Bias | AC14: Empirical SE | AD14: Estimated SE | AE14: Relative SE difference | AF14: Coverage | AG14: P(reject H0) | AI14: Effect | AJ14: True Value | AK14: Estimate | AL14: Empirical Bias | AM14: Relative Bias | AN14: Empirical SE | AO14: Estimated SE | AP14: Relative SE difference | AQ14: Coverage | AR14: P(reject H0)
B15: Intercept | C15: {=_xlfn.LET( _xlpm.keyA, J13, _xlpm.keyB, K13, _xlpm.rowKeys, B15:B21, _xlpm.colKeys, C14:K14, _xlpm.data, 'Batch Output'!$C:$Z, _xlpm.rowMatch, _xlfn.XMATCH(_xlpm.rowKeys, 'Batch Output'!$C:$C), _xlpm.colMatch, _xlfn.XMATCH(_xlpm.colKeys, 'Batch Output'!$1:$1), _xlpm.batchMatchRows, _xlfn._xlws.FILTER(ROW('Batch Output'!$A:$A), ('Batch Output'!$A:$A=_xlpm.keyA)*('Batch Output'!$B:$B=_xlpm.keyB)), _xlpm.firstMatchRow, INDEX(_xlpm.batchMatchRows, 1), INDEX(_xlpm.data, _xlpm.rowMatch + _xlpm.firstMatchRow - 2, _xlpm.colMatch - 2) )} -> 107.0774 | D15: 108.67323 | E15: 1.5958193 | F15: 1.476021 | G15: 1.454262 | H15: -0.014741699 | I15: 0.014903418 | J15: 0.811 | K15: 1 | M15: Intercept | N15: {=_xlfn.LET( _xlpm.keyA, U13, _xlpm.keyB, V13, _xlpm.rowKeys, M15:M21, _xlpm.colKeys, N14:V14, _xlpm.data, 'Batch Output'!$C:$Z, _xlpm.rowMatch, _xlfn.XMATCH(_xlpm.rowKeys, 'Batch Output'!$C:$C), _xlpm.colMatch, _xlfn.XMATCH(_xlpm.colKeys, 'Batch Output'!$1:$1), _xlpm.batchMatchRows, _xlfn._xlws.FILTER(ROW('Batch Output'!$A:$A), ('Batch Output'!$A:$A=_xlpm.keyA)*('Batch Output'!$B:$B=_xlpm.keyB)), _xlpm.firstMatchRow, INDEX(_xlpm.batchMatchRows, 1), INDEX(_xlpm.data, _xlpm.rowMatch + _xlpm.firstMatchRow - 2, _xlpm.colMatch - 2) )} -> 106.8125 | O15: 110.28618 | P15: 3.4737228 | Q15: 1.400649 | R15: 1.381191 | S15: -0.013891937 | T15: 0.032521701 | U15: 0.297 | V15: 1 | X15: Intercept | Y15: 107.08 | Z15: 108.7161 | AA15: 1.63872 | AB15: 0.0153 | AC15: 1.4509 | AD15: 1.4536 | AE15: 0.001891 | AF15: 0.788 | AG15: 1 | AI15: Intercept | AJ15: 106.81 | AK15: 110.2912 | AL15: 3.47874 | AM15: 0.03257 | AN15: 1.3848 | AO15: 1.3808 | AP15: -0.002916 | AQ15: 0.29 | AR15: 1 | AU15: V1 weights in fitting step
B16: age_strat_new | C16: -4.7686 | D16: -4.643123 | E16: 0.12551847 | F16: 0.549384 | G16: 0.54798 | H16: -0.002554454 | I16: -0.02632164 | J16: 0.943 | K16: 1 | M16: age_strat_new | N16: -4.7993 | O16: -4.600877 | P16: 0.19840508 | Q16: 0.546428 | R16: 0.551869 | S16: 0.0099577473 | T16: -0.041340576 | U16: 0.94 | V16: 1 | X16: age_strat_new | Y16: -4.77 | Z16: -4.6093 | AA16: 0.15932 | AB16: -0.03341 | AC16: 0.5626 | AD16: 0.5473 | AE16: -0.027131 | AF16: 0.946 | AG16: 1 | AI16: age_strat_new | AJ16: -4.8 | AK16: -4.581 | AL16: 0.21832 | AM16: -0.04549 | AN16: 0.5663 | AO16: 0.5525 | AP16: -0.024279 | AQ16: 0.928 | AR16: 1
B17: x12 | C17: 8.6967 | D17: 6.603724 | E17: -2.0929745 | F17: 0.332416 | G17: 0.32627 | H17: -0.018488642 | I17: -0.2406631 | J17: 0 | K17: 1 | M17: x12 | N17: 8.7022 | O17: 6.054166 | P17: -2.6480412 | Q17: 0.348446 | R17: 0.34387 | S17: -0.013133371 | T17: -0.30429534 | U17: 0 | V17: 1 | X17: x12 | Y17: 8.7 | Z17: 6.5949 | AA17: -2.1018 | AB17: -0.24168 | AC17: 0.3234 | AD17: 0.3256 | AE17: 0.00669 | AF17: 0 | AG17: 1 | AI17: x12 | AJ17: 8.7 | AK17: 6.059 | AL17: -2.64317 | AM17: -0.30374 | AN17: 0.344 | AO17: 0.3433 | AP17: -0.002098 | AQ17: 0 | AR17: 1
B18: x17 | C18: -1.6103 | D18: -1.934213 | E18: -0.32391876 | F18: 0.362362 | G18: 0.351039 | H18: -0.031247145 | I18: 0.20115497 | J18: 0.834 | K18: 1 | M18: x17 | N18: -1.5806 | O18: -2.335839 | P18: -0.75521355 | Q18: 0.348916 | R18: 0.343931 | S18: -0.014285968 | T18: 0.47779398 | U18: 0.423 | V18: 1 | X18: x17 | Y18: -1.61 | Z18: -1.9576 | AA18: -0.34734 | AB18: 0.2157 | AC18: 0.3486 | AD18: 0.3509 | AE18: 0.006702 | AF18: 0.834 | AG18: 1 | AI18: x17 | AJ18: -1.58 | AK18: -2.3485 | AL18: -0.76792 | AM18: 0.48584 | AN18: 0.3412 | AO18: 0.3436 | AP18: 0.006935 | AQ18: 0.397 | AR18: 1
B19: x18 | C19: -7.9152 | D19: -5.903691 | E19: 2.0114846 | F19: 0.409954 | G19: 0.420343 | H19: 0.02534211 | I19: -0.25413013 | J19: 0.001 | K19: 1 | M19: x18 | N19: -7.7764 | O19: -5.250221 | P19: 2.5262083 | Q19: 0.420879 | R19: 0.434742 | S19: 0.032938884 | T19: -0.32485455 | U19: 0 | V19: 1 | X19: x18 | Y19: -7.92 | Z19: -5.8924 | AA19: 2.0228 | AB19: -0.25556 | AC19: 0.4283 | AD19: 0.4205 | AE19: -0.018248 | AF19: 0.001 | AG19: 1 | AI19: x18 | AJ19: -7.78 | AK19: -5.2307 | AL19: 2.54572 | AM19: -0.32736 | AN19: 0.4485 | AO19: 0.435 | AP19: -0.030171 | AQ19: 0 | AR19: 1
B20: x6 | C20: 5.8681 | D20: 5.887471 | E20: 0.019331673 | F20: 0.030668 | G20: 0.030675 | H20: 0.0002468408 | I20: 0.0032943448 | J20: 0.908 | K20: 1 | M20: x6 | N20: 5.8644 | O20: 5.92699 | P20: 0.062579118 | Q20: 0.027499 | R20: 0.027351 | S20: -0.005364478 | T20: 0.010670998 | U20: 0.359 | V20: 1 | X20: x6 | Y20: 5.87 | Z20: 5.8861 | AA20: 0.01797 | AB20: 0.00306 | AC20: 0.0309 | AD20: 0.0305 | AE20: -0.012749 | AF20: 0.9 | AG20: 1 | AI20: x6 | AJ20: 5.86 | AK20: 5.9261 | AL20: 0.06166 | AM20: 0.01051 | AN20: 0.0273 | AO20: 0.0272 | AP20: -0.002391 | AQ20: 0.399 | AR20: 1
B21: y_bmi | C21: 0.0284 | D21: 0.031807 | E21: 0.0033906868 | F21: 0.01793 | G21: 0.017829 | H21: -0.00561925 | I21: 0.11932095 | J21: 0.947 | K21: 0.429 | M21: y_bmi | N21: 0.0321 | O21: 0.042995 | P21: 0.010886317 | Q21: 0.015392 | R21: 0.015321 | S21: -0.004613688 | T21: 0.33904895 | U21: 0.874 | V21: 0.803 | X21: y_bmi | Y21: 0.03 | Z21: 0.0331 | AA21: 0.00466 | AB21: 0.16388 | AC21: 0.0183 | AD21: 0.0178 | AE21: -0.028188 | AF21: 0.945 | AG21: 0.478 | AI21: y_bmi | AJ21: 0.03 | AK21: 0.0439 | AL21: 0.01176 | AM21: 0.36621 | AN21: 0.0154 | AO21: 0.0153 | AP21: -0.004561 | AQ21: 0.889 | AR21: 0.824
AU22: 2.1: use visit-level IPW weights instead of V1 weights
A23: [MI] [NOMISS V3] | B23: [PROC GENMOD][IND CORR][MI][RR_glm][NOMISS V3][bghhsub_s2] | M23: [PROC GENMOD][EXCH CORR][MI][RR_glm][NOMISS V3][bghhsub_s2] | X23: [PROC GENMOD][IND CORR][MI][RR_glm][NOMISS V3][bghhsub_s2][SUDAAN TRUE] | AI23: [PROC GENMOD][EXCH CORR][MI][RR_glm][NOMISS V3][bghhsub_s2][SUDAAN TRUE] | AS23: [MI] [NOMISS V3]
B24: Effect | C24: True Value | D24: Estimate | E24: Empirical Bias | F24: Relative Bias | G24: Empirical SE | H24: Estimated SE | I24: Relative SE difference | J24: Coverage | K24: P(reject H0) | M24: Effect | N24: True Value | O24: Estimate | P24: Empirical Bias | Q24: Relative Bias | R24: Empirical SE | S24: Estimated SE | T24: Relative SE difference | U24: Coverage | V24: P(reject H0) | X24: Effect | Y24: True Value | Z24: Estimate | AA24: Empirical Bias | AB24: Relative Bias | AC24: Empirical SE | AD24: Estimated SE | AE24: Relative SE difference | AF24: Coverage | AG24: P(reject H0) | AI24: Effect | AJ24: True Value | AK24: Estimate | AL24: Empirical Bias | AM24: Relative Bias | AN24: Empirical SE | AO24: Estimated SE | AP24: Relative SE difference | AQ24: Coverage | AR24: P(reject H0)
B25: Intercept | C25: 107.0774 | D25: 102.95711 | E25: -4.12029 | F25: -0.03848 | G25: 2.455818 | H25: 2.587164 | I25: 0.053484 | J25: 0.638 | K25: 0 | M25: Intercept | N25: 105.9799 | O25: 102.98236 | P25: -2.99757 | Q25: -0.02828 | R25: 2.651135 | S25: 2.748955 | T25: 0.036897 | U25: 0.805 | V25: 0 | X25: Intercept | Y25: 107.08 | Z25: 102.95711 | AA25: -4.12029 | AB25: -0.03848 | AC25: 2.455818 | AD25: 2.587164 | AE25: 0.053484 | AF25: 0.638 | AG25: 0 | AI25: Intercept | AJ25: 106.81 | AK25: 102.98236 | AL25: -3.83009 | AM25: -0.03586 | AN25: 2.651135 | AO25: 2.748955 | AP25: 0.036897 | AQ25: 0.703 | AR25: 0
B26: age_strat_new | C26: -4.7686 | D26: -4.218512 | E26: 0.55013 | F26: -0.11536 | G26: 0.989477 | H26: 1.023644 | I26: 0.034531 | J26: 0.929 | K26: 0 | M26: age_strat_new | N26: -5.1666 | O26: -4.160372 | P26: 1.0062 | Q26: -0.19475 | R26: 1.124162 | S26: 1.145951 | T26: 0.019383 | U26: 0.863 | V26: 0 | X26: age_strat_new | Y26: -4.77 | Z26: -4.218512 | AA26: 0.55013 | AB26: -0.11536 | AC26: 0.989477 | AD26: 1.023644 | AE26: 0.034531 | AF26: 0.929 | AG26: 0 | AI26: age_strat_new | AJ26: -4.8 | AK26: -4.160372 | AL26: 0.63891 | AM26: -0.13313 | AN26: 1.124162 | AO26: 1.145951 | AP26: 0.019383 | AQ26: 0.92 | AR26: 0
B27: x12 | C27: 8.6967 | D27: 8.547964 | E27: -0.14873 | F27: -0.0171 | G27: 0.560568 | H27: 0.561887 | I27: 0.002354 | J27: 0.948 | K27: 0 | M27: x12 | N27: 8.6968 | O27: 8.577834 | P27: -0.119 | Q27: -0.01368 | R27: 0.677665 | S27: 0.657046 | T27: -0.030426 | U27: 0.942 | V27: 0 | X27: x12 | Y27: 8.7 | Z27: 8.547964 | AA27: -0.14873 | AB27: -0.0171 | AC27: 0.560568 | AD27: 0.561887 | AE27: 0.002354 | AF27: 0.948 | AG27: 0 | AI27: x12 | AJ27: 8.7 | AK27: 8.577834 | AL27: -0.12437 | AM27: -0.01429 | AN27: 0.677665 | AO27: 0.657046 | AP27: -0.030426 | AQ27: 0.941 | AR27: 0
B28: x17 | C28: -1.6103 | D28: -1.04567 | E28: 0.56462 | F28: -0.35063 | G28: 0.571257 | H28: 0.600298 | I28: 0.050837 | J28: 0.856 | K28: 0 | M28: x17 | N28: -1.5934 | O28: -1.147678 | P28: 0.44576 | Q28: -0.27975 | R28: 0.627665 | S28: 0.637036 | T28: 0.014931 | U28: 0.89 | V28: 0 | X28: x17 | Y28: -1.61 | Z28: -1.04567 | AA28: 0.56462 | AB28: -0.35063 | AC28: 0.571257 | AD28: 0.600298 | AE28: 0.050837 | AF28: 0.856 | AG28: 0 | AI28: x17 | AJ28: -1.58 | AK28: -1.147678 | AL28: 0.43295 | AM28: -0.27391 | AN28: 0.627665 | AO28: 0.637036 | AP28: 0.014931 | AQ28: 0.893 | AR28: 0
B29: x18 | C29: -7.9152 | D29: -8.206118 | E29: -0.29094 | F29: 0.03676 | G29: 0.785912 | H29: 0.776122 | I29: -0.012458 | J29: 0.927 | K29: 0 | M29: x18 | N29: -7.9049 | O29: -8.118057 | P29: -0.21316 | Q29: 0.02697 | R29: 0.942763 | S29: 0.906104 | T29: -0.038884 | U29: 0.93 | V29: 0 | X29: x18 | Y29: -7.92 | Z29: -8.206118 | AA29: -0.29094 | AB29: 0.03676 | AC29: 0.785912 | AD29: 0.776122 | AE29: -0.012458 | AF29: 0.927 | AG29: 0 | AI29: x18 | AJ29: -7.78 | AK29: -8.118057 | AL29: -0.34163 | AM29: 0.04393 | AN29: 0.942763 | AO29: 0.906104 | AP29: -0.038884 | AQ29: 0.915 | AR29: 0
B30: x6 | C30: 5.8681 | D30: 6.048017 | E30: 0.17988 | F30: 0.03065 | G30: 0.056091 | H30: 0.05741 | I30: 0.023526 | J30: 0.134 | K30: 0 | M30: x6 | N30: 5.8287 | O30: 6.034798 | P30: 0.20614 | Q30: 0.03537 | R30: 0.058563 | S30: 0.06123 | T30: 0.045537 | U30: 0.122 | V30: 0 | X30: x6 | Y30: 5.87 | Z30: 6.048017 | AA30: 0.17988 | AB30: 0.03065 | AC30: 0.056091 | AD30: 0.05741 | AE30: 0.023526 | AF30: 0.134 | AG30: 0 | AI30: x6 | AJ30: 5.86 | AK30: 6.034798 | AL30: 0.17039 | AM30: 0.02905 | AN30: 0.058563 | AO30: 0.06123 | AP30: 0.045537 | AQ30: 0.21 | AR30: 0
B31: y_bmi | C31: 0.0284 | D31: 0.018427 | E31: -0.00999 | F31: -0.35154 | G31: 0.042598 | H31: 0.044226 | I31: 0.038208 | J31: 0.975 | K31: 0 | M31: y_bmi | N31: 0.068 | O31: 0.030219 | P31: -0.03782 | Q31: -0.55584 | R31: 0.046173 | S31: 0.047756 | T31: 0.034274 | U31: 0.919 | V31: 0 | X31: y_bmi | Y31: 0.03 | Z31: 0.018427 | AA31: -0.00999 | AB31: -0.35154 | AC31: 0.042598 | AD31: 0.044226 | AE31: 0.038208 | AF31: 0.975 | AG31: 0 | AI31: y_bmi | AJ31: 0.03 | AK31: 0.030219 | AL31: -0.00189 | AM31: -0.05883 | AN31: 0.046173 | AO31: 0.047756 | AP31: 0.034274 | AQ31: 0.979 | AR31: 0
A33: [MI] [NOMISS V3] | B33: [3][PROC GENMOD][IND CORR][MI][RR_glm][NOMISS V3][bghhsub_s2_v3_nr] | J33: =INDEX('Method Codes'!$B:$B, MATCH(B33, 'Method Codes'!$I:$I,0)) -> IND | K33: =INDEX('Method Codes'!H:H, MATCH(B33, 'Method Codes'!I:I,0)) -> 3A | M33: [3][PROC GENMOD][EXCH CORR][MI][RR_glm][NOMISS V3][bghhsub_s2_v3_nr] | U33: =INDEX('Method Codes'!$B:$B, MATCH(M33, 'Method Codes'!$I:$I,0)) -> EXCH | V33: =INDEX('Method Codes'!$H:$H, MATCH(M33, 'Method Codes'!$I:$I,0)) -> 3A | X33: [3][PROC GENMOD][IND CORR][MI][RR_glm][NOMISS V3][bghhsub_s2_v3_nr][SUDAAN TRUE] | AI33: [3][PROC GENMOD][EXCH CORR][MI][RR_glm][NOMISS V3][bghhsub_s2_v3_nr][SUDAAN TRUE] | AS33: [MI] [NOMISS V3]
B34: Effect | C34: True Value | D34: Estimate | E34: Empirical Bias | F34: Relative Bias | G34: Empirical SE | H34: Estimated SE | I34: Relative SE difference | J34: Coverage | K34: P(reject H0) | M34: Effect | N34: True Value | O34: Estimate | P34: Empirical Bias | Q34: Relative Bias | R34: Empirical SE | S34: Estimated SE | T34: Relative SE difference | U34: Coverage | V34: P(reject H0) | X34: Effect | Y34: True Value | Z34: Estimate | AA34: Empirical Bias | AB34: Relative Bias | AC34: Empirical SE | AD34: Estimated SE | AE34: Relative SE difference | AF34: Coverage | AG34: P(reject H0) | AI34: Effect | AJ34: True Value | AK34: Estimate | AL34: Empirical Bias | AM34: Relative Bias | AN34: Empirical SE | AO34: Estimated SE | AP34: Relative SE difference | AQ34: Coverage | AR34: P(reject H0) | AU34: 3
B35: Intercept | C35: {=_xlfn.LET( _xlpm.keyA, J33, _xlpm.keyB, K33, _xlpm.rowKeys, B35:B41, _xlpm.colKeys, C34:K34, _xlpm.data, 'Batch Output'!$C:$Z, _xlpm.rowMatch, _xlfn.XMATCH(_xlpm.rowKeys, 'Batch Output'!$C:$C), _xlpm.colMatch, _xlfn.XMATCH(_xlpm.colKeys, 'Batch Output'!$1:$1), _xlpm.batchMatchRows, _xlfn._xlws.FILTER(ROW('Batch Output'!$A:$A), ('Batch Output'!$A:$A=_xlpm.keyA)*('Batch Output'!$B:$B=_xlpm.keyB)), _xlpm.firstMatchRow, INDEX(_xlpm.batchMatchRows, 1), INDEX(_xlpm.data, _xlpm.rowMatch + _xlpm.firstMatchRow - 2, _xlpm.colMatch - 2) )} -> 107.0774 | D35: 107.01687 | E35: -0.060540082 | F35: 2.657191 | G35: 2.749209 | H35: 0.034629568 | I35: -0.000565386 | J35: 0.955 | K35: 0 | M35: Intercept | N35: {=_xlfn.LET( _xlpm.keyA, U33, _xlpm.keyB, V33, _xlpm.rowKeys, M35:M41, _xlpm.colKeys, N34:V34, _xlpm.data, 'Batch Output'!$C:$Z, _xlpm.rowMatch, _xlfn.XMATCH(_xlpm.rowKeys, 'Batch Output'!$C:$C), _xlpm.colMatch, _xlfn.XMATCH(_xlpm.colKeys, 'Batch Output'!$1:$1), _xlpm.batchMatchRows, _xlfn._xlws.FILTER(ROW('Batch Output'!$A:$A), ('Batch Output'!$A:$A=_xlpm.keyA)*('Batch Output'!$B:$B=_xlpm.keyB)), _xlpm.firstMatchRow, INDEX(_xlpm.batchMatchRows, 1), INDEX(_xlpm.data, _xlpm.rowMatch + _xlpm.firstMatchRow - 2, _xlpm.colMatch - 2) )} -> 106.8125 | O35: 107.36655 | P35: 0.55409432 | Q35: 3.230888 | R35: 3.306113 | S35: 0.023283156 | T35: 0.005187544 | U35: 0.949 | V35: 0 | X35: Intercept | Y35: 107.08 | Z35: 107.0543 | AA35: -0.0231 | AB35: -0.00022 | AC35: 2.697073 | AD35: 2.752775 | AE35: 0.020653 | AF35: 0.952 | AG35: 0 | AI35: Intercept | AJ35: 106.81 | AK35: 107.36186 | AL35: 0.54941 | AM35: 0.00514 | AN35: 3.209061 | AO35: 3.311775 | AP35: 0.032007 | AQ35: 0.943 | AR35: 0
B36: age_strat_new | C36: -4.7686 | D36: -5.043739 | E36: -0.27509719 | F36: 1.163428 | G36: 1.160315 | H36: -0.002675944 | I36: 0.057688796 | J36: 0.953 | K36: 0 | M36: age_strat_new | N36: -4.7993 | O36: -4.881287 | P36: -0.082004772 | Q36: 1.322258 | R36: 1.332442 | S36: 0.0077021496 | T36: 0.017086884 | U36: 0.961 | V36: 0 | X36: age_strat_new | Y36: -4.77 | Z36: -5.029648 | AA36: -0.26101 | AB36: 0.05473 | AC36: 1.162164 | AD36: 1.161337 | AE36: -0.000712 | AF36: 0.955 | AG36: 0 | AI36: age_strat_new | AJ36: -4.8 | AK36: -4.891761 | AL36: -0.09248 | AM36: 0.01927 | AN36: 1.316973 | AO36: 1.331685 | AP36: 0.011171 | AQ36: 0.96 | AR36: 0 | AU36: V3 sample + MI (with v1, v2, v3, IPW weights) + v3 IPW weights in fitting
B37: x12 | C37: 8.6967 | D37: 8.734776 | E37: 0.038077077 | F37: 0.633951 | G37: 0.630401 | H37: -0.005600024 | I37: 0.0043783369 | J37: 0.948 | K37: 0 | M37: x12 | N37: 8.7022 | O37: 8.734174 | P37: 0.031966465 | Q37: 0.717313 | R37: 0.693729 | S37: -0.032877594 | T37: 0.0036733744 | U37: 0.947 | V37: 0 | X37: x12 | Y37: 8.7 | Z37: 8.739232 | AA37: 0.04253 | AB37: 0.00489 | AC37: 0.614882 | AD37: 0.625931 | AE37: 0.017969 | AF37: 0.951 | AG37: 0 | AI37: x12 | AJ37: 8.7 | AK37: 8.739814 | AL37: 0.03761 | AM37: 0.00432 | AN37: 0.690579 | AO37: 0.689124 | AP37: -0.002106 | AQ37: 0.954 | AR37: 0
B38: x17 | C38: -1.6103 | D38: -1.306066 | E38: 0.30422904 | F38: 0.72019 | G38: 0.708292 | H38: -0.016520876 | I38: -0.18892757 | J38: 0.932 | K38: 0 | M38: x17 | N38: -1.5806 | O38: -1.436837 | P38: 0.14378863 | Q38: 0.880106 | R38: 0.862547 | S38: -0.019950744 | T38: -0.090969422 | U38: 0.95 | V38: 0 | X38: x17 | Y38: -1.61 | Z38: -1.33714 | AA38: 0.27315 | AB38: -0.16963 | AC38: 0.723672 | AD38: 0.706615 | AE38: -0.023569 | AF38: 0.932 | AG38: 0 | AI38: x17 | AJ38: -1.58 | AK38: -1.45497 | AL38: 0.12566 | AM38: -0.0795 | AN38: 0.881538 | AO38: 0.858368 | AP38: -0.026284 | AQ38: 0.949 | AR38: 0
B39: x18 | C39: -7.9152 | D39: -7.797711 | E39: 0.11746417 | F39: 0.81724 | G39: 0.822675 | H39: 0.0066499173 | I39: -0.014840374 | J39: 0.948 | K39: 0 | M39: x18 | N39: -7.7764 | O39: -7.79811 | P39: -0.021681434 | Q39: 0.903008 | R39: 0.901169 | S39: -0.002036483 | T39: 0.0027880965 | U39: 0.954 | V39: 0 | X39: x18 | Y39: -7.92 | Z39: -7.775615 | AA39: 0.13956 | AB39: -0.01763 | AC39: 0.832336 | AD39: 0.819308 | AE39: -0.015652 | AF39: 0.943 | AG39: 0 | AI39: x18 | AJ39: -7.78 | AK39: -7.728763 | AL39: 0.04767 | AM39: -0.00613 | AN39: 0.932676 | AO39: 0.897904 | AP39: -0.037282 | AQ39: 0.94 | AR39: 0
B40: x6 | C40: 5.8681 | D40: 5.907027 | E40: 0.038888087 | F40: 0.058436 | G40: 0.063544 | H40: 0.087423757 | I40: 0.0066269881 | J40: 0.95 | K40: 0 | M40: x6 | N40: 5.8644 | O40: 5.892187 | P40: 0.02777573 | Q40: 0.06445 | R40: 0.069494 | S40: 0.0782573 | T40: 0.0047363207 | U40: 0.966 | V40: 0 | X40: x6 | Y40: 5.87 | Z40: 5.904352 | AA40: 0.03621 | AB40: 0.00617 | AC40: 0.060449 | AD40: 0.063148 | AE40: 0.04465 | AF40: 0.948 | AG40: 0 | AI40: x6 | AJ40: 5.86 | AK40: 5.890148 | AL40: 0.02574 | AM40: 0.00439 | AN40: 0.065723 | AO40: 0.069316 | AP40: 0.05466 | AQ40: 0.974 | AR40: 0
B41: y_bmi | C41: 0.0284 | D41: -0.006987 | E41: -0.035403932 | F41: 0.049764 | G41: 0.052823 | H41: 0.061469334 | I41: -1.2458924 | J41: 0.951 | K41: 0 | M41: y_bmi | N41: 0.0321 | O41: 0.007868 | P41: -0.024240251 | Q41: 0.056615 | R41: 0.059601 | S41: 0.052731477 | T41: -0.75495065 | U41: 0.963 | V41: 0 | X41: y_bmi | Y41: 0.03 | Z41: -0.004237 | AA41: -0.03265 | AB41: -1.14909 | AC41: 0.050807 | AD41: 0.052906 | AE41: 0.041318 | AF41: 0.945 | AG41: 0 | AI41: y_bmi | AJ41: 0.03 | AK41: 0.010057 | AL41: -0.02205 | AM41: -0.68679 | AN41: 0.05699 | AO41: 0.059798 | AP41: 0.049269 | AQ41: 0.972 | AR41: 0
